Workbook
Name HINDI: Sheet2!$G$57:$G$64
Name NAME: Sheet2!$B$57:$G$64
Name SHALINI: Sheet2!$C$60:$G$60
Name SONALI: Sheet2!$B$57:$G$64

Sheet Sheet1
C3: A | D3: B | E3: C | F3: D | G3: E
B4: 1 | C4: GRADE | D4: BASIC | E4: HRA | F4: PF | G4: NET | J4: SUMIF
B5: 2 | C5: A | D5: 1000 | E5: 150 | F5: 80 | G5: 1070
B6: 3 | C6: B | D6: 4000 | E6: 600 | F6: 320 | G6: 4280
B7: 4 | C7: B | D7: 5000 | E7: 750 | F7: 400 | G7: 5350
B8: 5 | C8: A | D8: 3000 | E8: 450 | F8: 240 | G8: 3210
C11: =SUMIF(D5:D8,">=3500",G5:G8) -> 9630
C12: =SUMIF(D5:D8,">3500") -> 9000
C13: =SUMIF(C5:C8,"A",E5:E8) -> 600
C14: =SUMIF(F5:F8,"<=320") -> 640
C15: =SUMIF(F5:F8,"<=320",G5:G8) -> 8560

Sheet Sheet2
A1: NAME | B1: GRADE | C1: DEPT | D1: BASIC | E1: NET
A2: AJAY | B2: A | C2: A/C | D2: 1000 | E2: 1070
A3: SUNIL | B3: B | C3: H.R. | D3: 4000 | E3: 4280
A4: VIJAY | B4: B | C4: ADMN | D4: 5000 | E4: 5350
A5: ANIL | B5: A | C5: SALES | D5: 3000 | E5: 3210
B7: =AVERAGEIF(D2:D5,">=3500",E2:E5) -> 4815
B8: =AVERAGEIF(D2:D5,">=3500") -> 4500
B9: =AVERAGEIF(D2:D5,"A",B2:B5) -> #DIV/0!
B10: =AVERAGEIF(B2:B5,"A",D2:D5) -> 2000
C15: COUNT()
C18: A
B19: 1 | C19: SALES
B20: 2 | C20: 1000
B21: 3 | C21: 5000
B22: 4 | C22: 9000
B23: 5 | C23: 40003
C26: COUNTA()
C28: SR.NO | D28: A | E28: =COUNTA(C28:D32) -> 10
C29: 1 | D29: SALES
C30: 2 | D30: 1000
C31: 3 | D31: #DIV/0!
C32: 4 | D32: TRUE
C33: 5 | D33: 40003
C34: 6
C35: 7 | D35: 0.22916667
C39: SMALL
C41: A | D41: B | E41: =SMALL(C43:C47,1) -> 15
B42: 1 | C42: DATA-1 | D42: DATA-2 | E42: =SMALL(C43:C47,3) -> 18
B43: 2 | C43: 18 | D43: 14
B44: 3 | C44: 21 | D44: 16
B45: 4 | C45: 17 | D45: 12
B46: 5 | C46: 15 | D46: 14
B47: 6 | C47: 20 | D47: 16
D53: DEFINE NAME | E53: DEFINE NAME
K56: =SUM(SHALINI) -> 344
B57: NAME | C57: CLASS | D57: ENG | E57: MATHS | F57: CHE | G57: HINDI
B58: SONALI | C58: 12 | D58: 69 | E58: 73 | F58: 97 | G58: 97
B59: MADHU | C59: 12 | D59: 84 | E59: 87 | F59: 83 | G59: 86
B60: SHALINI | C60: 12 | D60: 95 | E60: 69 | F60: 74 | G60: 94
B61: SANDHYA | C61: 12 | D61: 99 | E61: 93 | F61: 79 | G61: 78 | I61: =MAX(SONALI) -> 99
...

Sheet Sheet3
C5: CONSOLIDATE 2
C7: SALESMAN NAME | D7: JAN | E7: FEB | F7: MAR | G7: APR | H7: MAY | I7: JUN
C8: RUTIK | D8: 12000 | E8: 11000 | F8: 34000 | G8: 21000 | H8: 20000 | I8: 10000
C9: SANKET | D9: 13000 | E9: 15000 | F9: 58000 | G9: 31000 | H9: 13000 | I9: 33000
C10: SAGAR | D10: 31000 | E10: 21000 | F10: 20000 | G10: 12000 | H10: 15000 | I10: 14000
C11: RUPESH | D11: 52000 | E11: 30000 | F11: 14000 | G11: 35000 | H11: 25000 | I11: 20000
C12: ANIL | D12: 12000 | E12: 24000 | F12: 31200 | G12: 51000 | H12: 31000 | I12: 11000
C13: TOTAL

Sheet Sheet4
C4: CONSOLIDATE 3
D9: SALESMAN NAME | E9: JAN | F9: FEB | G9: MAR | H9: APR | I9: MAY | J9: JUN
D10: RUTIK | E10: 13000 | F10: 14000 | G10: 38000 | H10: 23000 | I10: 22000 | J10: 12000
D11: SANKET | E11: 15000 | F11: 16000 | G11: 52000 | H11: 32000 | I11: 12000 | J11: 35000
D12: SAGAR | E12: 35000 | F12: 25000 | G12: 21000 | H12: 11000 | I12: 16000 | J12: 16000
D13: RUPESH | E13: 50000 | F13: 31000 | G13: 16000 | H13: 36000 | I13: 22000 | J13: 21000
D14: ANIL | E14: 10000 | F14: 26000 | G14: 33200 | H14: 55000 | I14: 32000 | J14: 10000
D15: TOTAL

Sheet Sheet5
C1: JAN | D1: FEB | E1: MAR | F1: APR | G1: MAY | H1: JUN
B2: Book1 | C2: =Sheet2!$C$136 -> 10000 | D2: =Sheet2!$D$136 -> 12000 | E2: =Sheet2!$E$136 -> 32000 | F2: =Sheet2!$F$136 -> 23000 | G2: =Sheet2!$G$136 -> 21000 | H2: =Sheet2!$H$136 -> 11000
B3: Book1 | C3: =Sheet3!$D$8 -> 12000 | D3: =Sheet3!$E$8 -> 11000 | E3: =Sheet3!$F$8 -> 34000 | F3: =Sheet3!$G$8 -> 21000 | G3: =Sheet3!$H$8 -> 20000 | H3: =Sheet3!$I$8 -> 10000
B4: Book1 | C4: =Sheet4!$E$10 -> 13000 | D4: =Sheet4!$F$10 -> 14000 | E4: =Sheet4!$G$10 -> 38000 | F4: =Sheet4!$H$10 -> 23000 | G4: =Sheet4!$I$10 -> 22000 | H4: =Sheet4!$J$10 -> 12000
A5: RUTIK | C5: =SUM(C2:C4) -> 35000 | D5: =SUM(D2:D4) -> 37000 | E5: =SUM(E2:E4) -> 104000 | F5: =SUM(F2:F4) -> 67000 | G5: =SUM(G2:G4) -> 63000 | H5: =SUM(H2:H4) -> 33000
B6: Book1 | C6: =Sheet2!$C$137 -> 10000 | D6: =Sheet2!$D$137 -> 17000 | E6: =Sheet2!$E$137 -> 54000 | F6: =Sheet2!$F$137 -> 32000 | G6: =Sheet2!$G$137 -> 12000 | H6: =Sheet2!$H$137 -> 32000
B7: Book1 | C7: =Sheet3!$D$9 -> 13000 | D7: =Sheet3!$E$9 -> 15000 | E7: =Sheet3!$F$9 -> 58000 | F7: =Sheet3!$G$9 -> 31000 | G7: =Sheet3!$H$9 -> 13000 | H7: =Sheet3!$I$9 -> 33000
B8: Book1 | C8: =Sheet4!$E$11 -> 15000 | D8: =Sheet4!$F$11 -> 16000 | E8: =Sheet4!$G$11 -> 52000 | F8: =Sheet4!$H$11 -> 32000 | G8: =Sheet4!$I$11 -> 12000 | H8: =Sheet4!$J$11 -> 35000
A9: SANKET | C9: =SUM(C6:C8) -> 38000 | D9: =SUM(D6:D8) -> 48000 | E9: =SUM(E6:E8) -> 164000 | F9: =SUM(F6:F8) -> 95000 | G9: =SUM(G6:G8) -> 37000 | H9: =SUM(H6:H8) -> 100000
B10: Book1 | C10: =Sheet2!$C$138 -> 32000 | D10: =Sheet2!$D$138 -> 23000 | E10: =Sheet2!$E$138 -> 21000 | F10: =Sheet2!$F$138 -> 11000 | G10: =Sheet2!$G$138 -> 13000 | H10: =Sheet2!$H$138 -> 15000
B11: Book1 | C11: =Sheet3!$D$10 -> 31000 | D11: =Sheet3!$E$10 -> 21000 | E11: =Sheet3!$F$10 -> 20000 | F11: =Sheet3!$G$10 -> 12000 | G11: =Sheet3!$H$10 -> 15000 | H11: =Sheet3!$I$10 -> 14000
B12: Book1 | C12: =Sheet4!$E$12 -> 35000 | D12: =Sheet4!$F$12 -> 25000 | E12: =Sheet4!$G$12 -> 21000 | F12: =Sheet4!$H$12 -> 11000 | G12: =Sheet4!$I$12 -> 16000 | H12: =Sheet4!$J$12 -> 16000
A13: SAGAR | C13: =SUM(C10:C12) -> 98000 | D13: =SUM(D10:D12) -> 69000 | E13: =SUM(E10:E12) -> 62000 | F13: =SUM(F10:F12) -> 34000 | G13: =SUM(G10:G12) -> 44000 | H13: =SUM(H10:H12) -> 45000
B14: Book1 | C14: =Sheet2!$C$139 -> 54000 | D14: =Sheet2!$D$139 -> 32000 | E14: =Sheet2!$E$139 -> 12000 | F14: =Sheet2!$F$139 -> 32000 | G14: =Sheet2!$G$139 -> 23000 | H14: =Sheet2!$H$139 -> 21000
B15: Book1 | C15: =Sheet3!$D$11 -> 52000 | D15: =Sheet3!$E$11 -> 30000 | E15: =Sheet3!$F$11 -> 14000 | F15: =Sheet3!$G$11 -> 35000 | G15: =Sheet3!$H$11 -> 25000 | H15: =Sheet3!$I$11 -> 20000
B16: Book1 | C16: =Sheet4!$E$13 -> 50000 | D16: =Sheet4!$F$13 -> 31000 | E16: =Sheet4!$G$13 -> 16000 | F16: =Sheet4!$H$13 -> 36000 | G16: =Sheet4!$I$13 -> 22000 | H16: =Sheet4!$J$13 -> 21000
A17: RUPESH | C17: =SUM(C14:C16) -> 156000 | D17: =SUM(D14:D16) -> 93000 | E17: =SUM(E14:E16) -> 42000 | F17: =SUM(F14:F16) -> 103000 | G17: =SUM(G14:G16) -> 70000 | H17: =SUM(H14:H16) -> 62000
B18: Book1 | C18: =Sheet2!$C$140 -> 14000 | D18: =Sheet2!$D$140 -> 26000 | E18: =Sheet2!$E$140 -> 32200 | F18: =Sheet2!$F$140 -> 54000 | G18: =Sheet2!$G$140 -> 32000 | H18: =Sheet2!$H$140 -> 12000
B19: Book1 | C19: =Sheet3!$D$12 -> 12000 | D19: =Sheet3!$E$12 -> 24000 | E19: =Sheet3!$F$12 -> 31200 | F19: =Sheet3!$G$12 -> 51000 | G19: =Sheet3!$H$12 -> 31000 | H19: =Sheet3!$I$12 -> 11000
B20: Book1 | C20: =Sheet4!$E$14 -> 10000 | D20: =Sheet4!$F$14 -> 26000 | E20: =Sheet4!$G$14 -> 33200 | F20: =Sheet4!$H$14 -> 55000 | G20: =Sheet4!$I$14 -> 32000 | H20: =Sheet4!$J$14 -> 10000
A21: ANIL | C21: =SUM(C18:C20) -> 36000 | D21: =SUM(D18:D20) -> 76000 | E21: =SUM(E18:E20) -> 96600 | F21: =SUM(F18:F20) -> 160000 | G21: =SUM(G18:G20) -> 95000 | H21: =SUM(H18:H20) -> 33000
A22: TOTAL
E28: SUBTOTAL
B30: PID | C30: RANG NO | D30: NAME OF PERSON | E30: AGE | F30: DEPARTMENT | H30: SALES-2016 | I30: SALES-2017 | J30: SALES 2016/20117
B31: 101 | C31: 213423 | D31: AVINASH | E31: 32 | F31: GARMENT | G31: AUG | H31: 1150 | I31: 1400 | J31: 2650
G32: AUG Total | J32: =SUBTOTAL(9,J31:J31) -> 2650
B33: 107 | C33: 213423 | D33: SANDHYA | E33: 31 | F33: FURNITURE | G33: DEC | H33: 1280 | I33: 3200 | J33: 4480
G34: DEC Total | J34: =SUBTOTAL(9,J33:J33) -> 4480
B35: 103 | C35: 213423 | D35: NISHA | E35: 32 | F35: GARMENT | G35: FEB | H35: 1200 | I35: 1100 | J35: 2300
G36: FEB Total | J36: =SUBTOTAL(9,J35:J35) -> 2300
B37: 104 | C37: 213423 | D37: MANISHA | E37: 30 | F37: GARMENT | G37: JAN | H37: 1100 | I37: 1230 | J37: 2330
B38: 108 | C38: 213423 | D38: MITHUN | E38: 32 | F38: ELECTRONICS | G38: JAN | H38: 1232 | I38: 2100 | J38: 3332
B39: 105 | C39: 213423 | D39: MANISHA | E39: 30 | F39: FURNITURE | G39: JAN | H39: 800 | I39: 1240 | J39: 2040
G40: JAN Total | J40: =SUBTOTAL(9,J37:J39) -> 7702
B41: 106 | C41: 213423 | D41: SONALI | E41: 31 | F41: ELECTRONICS | G41: MAR | H41: 1134 | I41: 2200 | J41: 3334
B42: 102 | C42: 213423 | D42: SUPRIYA | E42: 31 | F42: GARMENT | G42: MAR | H42: 1200 | I42: 1300 | J42: 2500
G43: MAR Total | J43: =SUBTOTAL(9,J41:J42) -> 5834
G44: Grand Total | J44: =SUBTOTAL(9,J31:J42) -> 22966
D48: WHAT IF ANALYSIS
C49: STEP 1
...

Sheet Sheet6
